Workbook
Name cote_total_1: 'Bulletin'!$G$197
Name cote_total_2: 'Bulletin'!$H$197
Name cote_total_3: 'Bulletin'!$I$197
Name moy_total_1: 'Bulletin'!$G194
Name moy_total_2: 'Bulletin'!$H194
Name moy_total_3: 'Bulletin'!$I194

Sheet Bulletin
A1: IPD BIYEMASSI LYCEE 694638049 fohom.william.francis@emailboxy.cm | J1: IPD BIYEMASSI LYCEE 694638049 fohom.william.francis@emailboxy.cm
A2: BULLETIN DE NOTES
A3: PREMIER TRIMESTRE - Année scolaire : 2024/2025
A4: Nom et Prénom | C4: NOAH DAVIS | L4: Matricule | M4: IPD6789
A5: Date de naissance | C5: 05/11/2011 | E5: à | L5: Redoublant
A6: Sexe | C6: Féminin | L6: Parent
A7: Classe | C7: CM2 | L7: Contact
F9: Matières/Compétences | I9: Modules/Unités d'apprentissage | L9: UA1 | O9: UA2 | Q9: SEQ3
L10: NOTE | M10: COTE | O10: NOTE | P10: COTE | Q10: NOTE
F11: Français | I11: Standard/Ecrit: 20 pts | K11: 20 | L11: 17 | N11: 20 | O11: 19 | Q11: 0
I12: Oral: 20 pts | K12: 20 | L12: 14 | N12: 20 | O12: 20 | Q12: 0
I13: Pratique: 20 pts | K13: 20 | L13: 16 | N13: 20 | O13: 18 | Q13: 0
I14: Savoir-Etre: 20 pts | K14: 20 | L14: 12 | N14: 20 | O14: 16 | Q14: 0
F15: Total | K15: 80 | L15: 59 | M15: A | N15: 80 | O15: 73 | P15: A+ | Q15: =SUM(Q11:Q14)
F16: COTE | L16: A
F17: Histoire | I17: Standard/Ecrit: 20 pts | K17: 20 | L17: 14 | N17: 20 | O17: 8 | Q17: 0
I18: Oral: 20 pts | K18: 20 | L18: 12 | N18: 20 | O18: 16 | Q18: 0
I19: Pratique: 20 pts | K19: 20 | L19: 20 | N19: 20 | O19: 17 | Q19: 0
I20: Savoir-Etre: 20 pts | K20: 20 | L20: 13 | N20: 20 | O20: 17 | Q20: 0
F21: Total | K21: 80 | L21: 59 | M21: A | N21: 80 | O21: 58 | P21: A | Q21: =SUM(Q17:Q20)
F22: COTE | L22: A
F23: Géographie | I23: Standard/Ecrit: 20 pts | K23: 20 | L23: 13 | N23: 20 | O23: 13 | Q23: 0
I24: Oral: 20 pts | K24: 20 | L24: 10 | N24: 20 | O24: 13 | Q24: 0
I25: Pratique: 20 pts | K25: 20 | L25: 19 | N25: 20 | O25: 13 | Q25: 0
I26: Savoir-Etre: 20 pts | K26: 20 | L26: 19 | N26: 20 | O26: 16 | Q26: 0
F27: Total | K27: 80 | L27: 61 | M27: A | N27: 80 | O27: 55 | P27: ECA | Q27: =SUM(Q23:Q26)
F28: COTE | L28: A
F29: Anglais | I29: Pratique: 20 pts | K29: 20 | L29: 14 | N29: 20 | O29: 13 | Q29: 0
I30: Oral: 20 pts | K30: 20 | L30: 12 | N30: 20 | O30: 19 | Q30: 0
I31: Standard/Ecrit: 20 pts | K31: 20 | L31: 11 | N31: 20 | O31: 10 | Q31: 0
I32: Savoir-Etre: 20 pts | K32: 20 | L32: 8 | N32: 20 | O32: 12 | Q32: 0
F33: Total | K33: 80 | L33: 45 | M33: ECA | N33: 80 | O33: 54 | P33: ECA | Q33: =SUM(Q29:Q32)
F34: COTE | L34: ECA
A35: COMMUNIQUER EN FRANCAIS ET ANGLAIS ET PRATIQUER AU MOINS UNE LANGUE NATIONALE | F35: Éducation Civique | I35: Pratique: 20 pts | K35: 20 | L35: 17 | N35: 20 | O35: 10 | Q35: 0
I36: Oral: 20 pts | K36: 20 | L36: 10 | N36: 20 | O36: 19 | Q36: 0
I37: Standard/Ecrit: 20 pts | K37: 20 | L37: 11 | N37: 20 | O37: 11 | Q37: 0
I38: Savoir-Etre: 20 pts | K38: 20 | L38: 14 | N38: 20 | O38: 20 | Q38: 0
F39: Total | K39: 80 | L39: 52 | M39: ECA | N39: 80 | O39: 60 | P39: A | Q39: =SUM(Q35:Q38)
F40: COTE | L40: ECA
F41: Arts Plastiques | I41: Pratique: 20 pts | K41: 20 | L41: 9 | N41: 20 | O41: 15 | Q41: 0
...

Sheet Stats
A1: Id_evaluation | B1: Student | C1: class_module_id | D1: Module_id | E1: Module_name | F1: class_module_period | G1: class_module_classe | H1: class_module_school | I1: module_notation | J1: evaluation_note | K1: evaluation_time_id | L1: evaluation_time_name | M1: Student_id | N1: Student_class_id | O1: Student_class_name | P1: Student_class_period_id | Q1: Student_class_period_name | R1: Student_registration_number
A2: 1211 | B2: Francis William | C2: 1 | D2: 9 | E2: Standard/Ecrit | F2: 2024/2025 | G2: CM2 | H2: IPD | I2: 20 | J2: 17 | K2: 7 | L2: Mois 1 | M2: 4 | N2: 1 | O2: CM2 | P2: 1 | Q2: 2024/2025 | R2: IPD00004
A3: 1212 | B3: Francis William | C3: 2 | D3: 10 | E3: Oral | F3: 2024/2025 | G3: CM2 | H3: IPD | I3: 20 | J3: 9 | K3: 7 | L3: Mois 1 | M3: 4 | N3: 1 | O3: CM2 | P3: 1 | Q3: 2024/2025 | R3: IPD00004
A4: 1213 | B4: Francis William | C4: 3 | D4: 9 | E4: Standard/Ecrit | F4: 2024/2025 | G4: CM2 | H4: IPD | I4: 20 | J4: 0 | K4: 7 | L4: Mois 1 | M4: 4 | N4: 1 | O4: CM2 | P4: 1 | Q4: 2024/2025 | R4: IPD00004
A5: 1214 | B5: Francis William | C5: 4 | D5: 9 | E5: Standard/Ecrit | F5: 2024/2025 | G5: CM2 | H5: IPD | I5: 20 | J5: 0 | K5: 7 | L5: Mois 1 | M5: 4 | N5: 1 | O5: CM2 | P5: 1 | Q5: 2024/2025 | R5: IPD00004
A6: 1215 | B6: Francis William | C6: 5 | D6: 9 | E6: Standard/Ecrit | F6: 2024/2025 | G6: CM2 | H6: IPD | I6: 20 | J6: 0 | K6: 7 | L6: Mois 1 | M6: 4 | N6: 1 | O6: CM2 | P6: 1 | Q6: 2024/2025 | R6: IPD00004
A7: 1216 | B7: Francis William | C7: 6 | D7: 10 | E7: Oral | F7: 2024/2025 | G7: CM2 | H7: IPD | I7: 20 | J7: 0 | K7: 7 | L7: Mois 1 | M7: 4 | N7: 1 | O7: CM2 | P7: 1 | Q7: 2024/2025 | R7: IPD00004
A8: 1217 | B8: Francis William | C8: 7 | D8: 10 | E8: Oral | F8: 2024/2025 | G8: CM2 | H8: IPD | I8: 20 | J8: 0 | K8: 7 | L8: Mois 1 | M8: 4 | N8: 1 | O8: CM2 | P8: 1 | Q8: 2024/2025 | R8: IPD00004
A9: 1218 | B9: Francis William | C9: 8 | D9: 10 | E9: Oral | F9: 2024/2025 | G9: CM2 | H9: IPD | I9: 20 | J9: 0 | K9: 7 | L9: Mois 1 | M9: 4 | N9: 1 | O9: CM2 | P9: 1 | Q9: 2024/2025 | R9: IPD00004
A10: 1219 | B10: Francis William | C10: 9 | D10: 10 | E10: Oral | F10: 2024/2025 | G10: CM2 | H10: IPD | I10: 20 | J10: 0 | K10: 7 | L10: Mois 1 | M10: 4 | N10: 1 | O10: CM2 | P10: 1 | Q10: 2024/2025 | R10: IPD00004
A11: 1220 | B11: Francis William | C11: 10 | D11: 9 | E11: Standard/Ecrit | F11: 2024/2025 | G11: CM2 | H11: IPD | I11: 20 | J11: 0 | K11: 7 | L11: Mois 1 | M11: 4 | N11: 1 | O11: CM2 | P11: 1 | Q11: 2024/2025 | R11: IPD00004
A12: 1221 | B12: Francis William | C12: 11 | D12: 11 | E12: Pratique | F12: 2024/2025 | G12: CM2 | H12: IPD | I12: 20 | J12: 17 | K12: 7 | L12: Mois 1 | M12: 4 | N12: 1 | O12: CM2 | P12: 1 | Q12: 2024/2025 | R12: IPD00004
A13: 1222 | B13: Francis William | C13: 12 | D13: 11 | E13: Pratique | F13: 2024/2025 | G13: CM2 | H13: IPD | I13: 20 | J13: 0 | K13: 7 | L13: Mois 1 | M13: 4 | N13: 1 | O13: CM2 | P13: 1 | Q13: 2024/2025 | R13: IPD00004
... A881: 2090 | B881: Ava Anderson 2 | C881: 40 | D881: 12 | E881: Savoir-Etre | F881: 2024/2025 | G881: CM2 | H881: IPD | I881: 20 | J881: 0 | K881: 8 | L881: Mois 2 | M881: 26 | N881: 1 | O881: CM2 | P881: 1 | Q881: 2024/2025 | R881: IPD1244

Sheet Analysis
C1: Première séquence | D1: Deuxieme séquence | E1: Deuxieme séquence | G1: Première séquence | H1: Deuxieme séquence | I1: Deuxieme séquence | K1: Première séquence | L1: Deuxieme séquence | M1: Deuxieme séquence
C2: IPD | D2: IPD | E2: IPD | G2: IPD | H2: IPD | I2: IPD | K2: IPD | L2: IPD | M2: IPD
C3: CM2 | D3: CM2 | E3: CM2 | G3: CM2 | H3: CM2 | I3: CM2 | K3: CM2 | L3: CM2 | M3: CM2
C4: 2024/2025 | D4: 2024/2025 | E4: 2024/2025 | G4: 2024/2025 | H4: 2024/2025 | I4: 2024/2025 | K4: 2024/2025 | L4: 2024/2025 | M4: 2024/2025
A5: IPD3456 | B5: Francis William | C5: =SUMIFS(Stats!$J:$J,Stats!$B:$B,$B5,Stats!$L:$L,C$1,Stats!$F:$F,C$4,Stats!$G:$G,C$3,Stats!$H:$H,C$2) | D5: =SUMIFS(Stats!$J:$J,Stats!$B:$B,$B5,Stats!$L:$L,D$1,Stats!$F:$F,D$4,Stats!$G:$G,D$3,Stats!$H:$H,D$2) | E5: =SUMIFS(Stats!$J:$J,Stats!$B:$B,$B5,Stats!$L:$L,E$1,Stats!$F:$F,E$4,Stats!$G:$G,E$3,Stats!$H:$H,E$2) | G5: =SUMIFS(Stats!$I:$I,Stats!$B:$B,$B5,Stats!$L:$L,G$1,Stats!$F:$F,G$4,Stats!$G:$G,G$3,Stats!$H:$H,G$2) | H5: =SUMIFS(Stats!$I:$I,Stats!$B:$B,$B5,Stats!$L:$L,H$1,Stats!$F:$F,H$4,Stats!$G:$G,H$3,Stats!$H:$H,H$2) | I5: =SUMIFS(Stats!$I:$I,Stats!$B:$B,$B5,Stats!$L:$L,I$1,Stats!$F:$F,I$4,Stats!$G:$G,I$3,Stats!$H:$H,I$2) | K5: =IFERROR(C5/G5*20,0) | L5: =IFERROR(D5/H5*20,0) | M5: =IFERROR(E5/I5*20,0) | N5: =_xlfn.RANK.EQ(K5,$K$5:$K$5000,0) | O5: =_xlfn.RANK.EQ(L5,$L$5:$L$5000,0) | P5: =_xlfn.RANK.EQ(M5,$M$5:$M$5000,0) | Q5: =IFERROR(SUM(C5:E5)/SUM(G5:I5)*20,0) | R5: =_xlfn.RANK.EQ(Q5,$Q$5:$Q$5000,0) | S5: =IFERROR(AVERAGEIF(C5:E5,">0"),0) | T5: =IFERROR(AVERAGEIF(G5:I5,">0"),0)
A6: IPD1234 | B6: John Doe
A7: IPD9012 | B7: Alex Brown
A8: IPD3456 | B8: Emma Jones
A9: IPD7890 | B9: Liam Wilson
A10: IPD1244 | B10: Sophia Martin
A11: IPD1244 | B11: Noah Davis
A12: IPD1244 | B12: Mia Moore
A13: IPD4567 | B13: Lucas Taylor
A14: IPD1243 | B14: Ava Anderson
A15: IPD1244 | B15: Ava Anderson 2
